<?xml version="1.0" ?>
<robot name="GEN3_URDF_V12" xmlns:xacro="http://ros.org/wiki/xacro">
    <xacro:include filename="$(find gripper)/urdf/robotiq_arg85_description.xacro"/>

  
  <link name="world">
  </link>

   <joint name="fixed" type="fixed">
    <parent link="world"/>
    <child link="base_link"/>
  </joint>

  <link name="base_link">
    <inertial>
      <origin xyz="-0.000648 -0.000166 0.084487" rpy="0 0 0" />
      <mass value="1.697" />
      <inertia ixx="0.004622" ixy="9E-06" ixz="6E-05" iyy="0.004495" iyz="9E-06" izz="0.002079" />
    </inertial>
    <visual>
      <origin xyz="0 0 0" rpy="0 0 0" />
      <geometry>
        <mesh filename="package://kinova_description/meshes/base_link.STL" />
      </geometry>
      <material name="">
        <color rgba="0.75294 0.75294 0.75294 1" />
      </material>
    </visual>
    <collision>
      <origin xyz="0 0 0" rpy="0 0 0" />
      <geometry>
        <mesh filename="package://kinova_description/meshes/base_link.STL" />
      </geometry>
    </collision>
  </link>

  <link name="Shoulder_Link">
    <inertial>
      <origin xyz="-2.3E-05 -0.010364 -0.07336" rpy="0 0 0" />
      <mass value="1.3773" />
      <inertia ixx="0.00457" ixy="1E-06" ixz="2E-06" iyy="0.004831" iyz="0.000448" izz="0.001409" />
    </inertial>
    <visual>
      <origin xyz="0 0 0" rpy="0 0 0" />
      <geometry>
        <mesh filename="package://kinova_description/meshes/shoulder_link.STL" />
      </geometry>
      <material name="">
        <color rgba="0.75294 0.75294 0.75294 1" />
      </material>
    </visual>
    <collision>
      <origin xyz="0 0 0" rpy="0 0 0" />
      <geometry>
        <mesh filename="package://kinova_description/meshes/shoulder_link.STL" />
      </geometry>
    </collision>
  </link>

  <joint name="Actuator1" type="continuous">
    <origin xyz="0 0 0.15643" rpy="3.1416 2.7629E-18 -4.9305E-36" />
    <parent link="base_link" />
    <child link="Shoulder_Link" />
    <axis xyz="0 0 1" />
    <limit effort="39" velocity="0.8727" />
  </joint>

   <transmission name="trans_Actuator1">
      <type>transmission_interface/SimpleTransmission</type>
      <joint name="Actuator1">
        <hardwareInterface>hardware_interface/EffortJointInterface</hardwareInterface>
      </joint>
      <actuator name="motor_Actuator1">
        <hardwareInterface>hardware_interface/EffortJointInterface</hardwareInterface>
        <mechanicalReduction>1</mechanicalReduction>
      </actuator>
    </transmission>

  <link name="HalfArm1_Link">
    <inertial>
      <origin xyz="-4.4E-05 -0.09958 -0.013278" rpy="0 0 0" />
      <mass value="1.1636" />
      <inertia ixx="0.011088" ixy="5E-06" ixz="0" iyy="0.001072" iyz="-0.000691" izz="0.011255" />
    </inertial>
    <visual>
      <origin xyz="0 0 0" rpy="0 0 0" />
      <geometry>
        <mesh filename="package://kinova_description/meshes/half_arm_1_link.STL" />
      </geometry>
      <material name="">
        <color rgba="0.75294 0.75294 0.75294 1" />
      </material>
    </visual>
    <collision>
      <origin xyz="0 0 0" rpy="0 0 0" />
      <geometry>
        <mesh filename="package://kinova_description/meshes/half_arm_1_link.STL" />
      </geometry>
    </collision>
  </link>

  <joint name="Actuator2" type="revolute">
    <origin xyz="0 0.005375 -0.12838" rpy="1.5708 2.1343E-17 -1.1102E-16" />
    <parent link="Shoulder_Link" />
    <child link="HalfArm1_Link" />
    <axis xyz="0 0 1" />
    <limit lower="-2.41" upper="2.41" effort="39" velocity="0.8727" />
  </joint>

   <transmission name="trans_Actuator2">
      <type>transmission_interface/SimpleTransmission</type>
      <joint name="Actuator2">
        <hardwareInterface>hardware_interface/EffortJointInterface</hardwareInterface>
      </joint>
      <actuator name="motor_Actuator2">
        <hardwareInterface>hardware_interface/EffortJointInterface</hardwareInterface>
        <mechanicalReduction>1</mechanicalReduction>
      </actuator>
    </transmission>

  <link name="HalfArm2_Link">
    <inertial>
      <origin xyz="-4.4E-05 -0.006641 -0.117892" rpy="0 0 0" />
      <mass value="1.1636" />
      <inertia ixx="0.010932" ixy="0" ixz="-7E-06" iyy="0.011127" iyz="0.000606" izz="0.001043" />
    </inertial>
    <visual>
      <origin xyz="0 0 0" rpy="0 0 0" />
      <geometry>
        <mesh filename="package://kinova_description/meshes/half_arm_2_link.STL" />
      </geometry>
      <material name="">
        <color rgba="0.75294 0.75294 0.75294 1" />
      </material>
    </visual>
    <collision>
      <origin xyz="0 0 0" rpy="0 0 0" />
      <geometry>
        <mesh filename="package://kinova_description/meshes/half_arm_2_link.STL" />
      </geometry>
    </collision>
  </link>

  <joint name="Actuator3" type="continuous">
    <origin xyz="0 -0.21038 -0.006375" rpy="-1.5708 1.2326E-32 -2.9122E-16" />
    <parent link="HalfArm1_Link" />
    <child link="HalfArm2_Link" />
    <axis xyz="0 0 1" />
    <limit effort="39" velocity="0.8727" />
  </joint>

   <transmission name="trans_Actuator3">
      <type>transmission_interface/SimpleTransmission</type>
      <joint name="Actuator3">
        <hardwareInterface>hardware_interface/EffortJointInterface</hardwareInterface>
      </joint>
      <actuator name="motor_Actuator3">
        <hardwareInterface>hardware_interface/EffortJointInterface</hardwareInterface>
        <mechanicalReduction>1</mechanicalReduction>
      </actuator>
    </transmission>

  <link name="ForeArm_Link">
    <inertial>
      <origin xyz="-1.8E-05 -0.075478 -0.015006" rpy="0 0 0" />
      <mass value="0.9302" />
      <inertia ixx="0.008147" ixy="-1E-06" ixz="0" iyy="0.000631" iyz="-0.0005" izz="0.008316" />
    </inertial>
    <visual>
      <origin xyz="0 0 0" rpy="0 0 0" />
      <geometry>
        <mesh filename="package://kinova_description/meshes/forearm_link.STL" />
      </geometry>
      <material name="">
        <color rgba="0.75294 0.75294 0.75294 1" />
      </material>
    </visual>
    <collision>
      <origin xyz="0 0 0" rpy="0 0 0" />
      <geometry>
        <mesh filename="package://kinova_description/meshes/forearm_link.STL" />
      </geometry>
    </collision>
  </link>

  <joint name="Actuator4" type="revolute">
    <origin xyz="0 0.006375 -0.21038" rpy="1.5708 -6.6954E-17 -1.6653E-16" />
    <parent link="HalfArm2_Link" />
    <child link="ForeArm_Link" />
    <axis xyz="0 0 1" />
    <limit lower="-2.66" upper="2.66" effort="39" velocity="0.8727" />
  </joint>

     <transmission name="trans_Actuator4">
      <type>transmission_interface/SimpleTransmission</type>
      <joint name="Actuator4">
        <hardwareInterface>hardware_interface/PositionJointInterface</hardwareInterface>
      </joint>
      <actuator name="motor_Actuator4">
        <hardwareInterface>hardware_interface/PositionJointInterface</hardwareInterface>
        <mechanicalReduction>1</mechanicalReduction>
      </actuator>
    </transmission>

  <link name="SphericalWrist1_Link">
    <inertial>
      <origin xyz="1E-06 -0.009432 -0.063883" rpy="0 0 0" />
      <mass value="0.6781" />
      <inertia ixx="0.001596" ixy="0" ixz="0" iyy="0.001607" iyz="0.000256" izz="0.000399" />
    </inertial>
    <visual>
      <origin xyz="0 0 0" rpy="0 0 0" />
      <geometry>
        <mesh filename="package://kinova_description/meshes/spherical_wrist_1_link.STL" />
      </geometry>
      <material name="">
        <color rgba="0.75294 0.75294 0.75294 1" />
      </material>
    </visual>
    <collision>
      <origin xyz="0 0 0" rpy="0 0 0" />
      <geometry>
        <mesh filename="package://kinova_description/meshes/spherical_wrist_1_link.STL" />
      </geometry>
    </collision>
  </link>

  <joint name="Actuator5" type="continuous">
    <origin xyz="0 -0.20843 -0.006375" rpy="-1.5708 2.2204E-16 -6.373E-17" />
    <parent link="ForeArm_Link" />
    <child link="SphericalWrist1_Link" />
    <axis xyz="0 0 1" />
    <limit effort="9" velocity="0.8727" />
  </joint>

     <transmission name="trans_Actuator5">
      <type>transmission_interface/SimpleTransmission</type>
      <joint name="Actuator5">
        <hardwareInterface>hardware_interface/PositionJointInterface</hardwareInterface>
      </joint>
      <actuator name="motor_Actuator5">
        <hardwareInterface>hardware_interface/PositionJointInterface</hardwareInterface>
        <mechanicalReduction>1</mechanicalReduction>
      </actuator>
    </transmission>


  <link name="SphericalWrist2_Link">
    <inertial>
      <origin xyz="1E-06 -0.045483 -0.00965" rpy="0 0 0" />
      <mass value="0.6781" />
      <inertia ixx="0.001641" ixy="0" ixz="0" iyy="0.00041" iyz="-0.000278" izz="0.001641" />
    </inertial>
    <visual>
      <origin xyz="0 0 0" rpy="0 0 0" />
      <geometry>
        <mesh filename="package://kinova_description/meshes/spherical_wrist_2_link.STL" />
      </geometry>
      <material name="">
        <color rgba="0.75294 0.75294 0.75294 1" />
      </material>
    </visual>
    <collision>
      <origin xyz="0 0 0" rpy="0 0 0" />
      <geometry>
        <mesh filename="package://kinova_description/meshes/spherical_wrist_2_link.STL" />
      </geometry>
    </collision>
  </link>

  <joint name="Actuator6" type="revolute">
    <origin xyz="0 0.00017505 -0.10593" rpy="1.5708 9.2076E-28 -8.2157E-15" />
    <parent link="SphericalWrist1_Link" />
    <child link="SphericalWrist2_Link" />
    <axis xyz="0 0 1" />
    <limit lower="-2.23" upper="2.23" effort="15" velocity="10.8727" />
  </joint>

     <transmission name="trans_Actuator6">
      <type>transmission_interface/SimpleTransmission</type>
      <joint name="Actuator6">
        <hardwareInterface>hardware_interface/PositionJointInterface</hardwareInterface>
      </joint>
      <actuator name="motor_Actuator6">
        <hardwareInterface>hardware_interface/PositionJointInterface</hardwareInterface>
        <mechanicalReduction>1</mechanicalReduction>
      </actuator>
    </transmission>

  <link name="Bracelet_Link">
    <inertial>
      <origin xyz="-0.000281 -0.011402 -0.029798" rpy="0 0 0" />
      <mass value="0.5006" />
      <inertia ixx="0.000587" ixy="3E-06" ixz="3E-06" iyy="0.000369" iyz="0.000118" izz="0.000609" />
    </inertial>
    <visual>
      <origin xyz="0 0 0" rpy="0 0 0" />
      <geometry>
        <mesh filename="package://kinova_description/meshes/bracelet_with_vision_link.STL" />
      </geometry>
      <material name="">
        <color rgba="0.75294 0.75294 0.75294 1" />
      </material>
    </visual>
    <collision>
      <origin xyz="0 0 0" rpy="0 0 0" />
      <geometry>
        <mesh filename="package://kinova_description/meshes/bracelet_with_vision_link.STL" />
      </geometry>
    </collision>
  </link>

 <link name="tool">
        <visual>
            <origin rpy="0 0 0" xyz="0.01 0.0 0.1"/>
            <geometry>
                <box size = "0.02 0.02 0.2"/>
            </geometry>
        </visual>
        <collision>
          <origin xyz="0.01 -0.01 0.1" rpy="0 0 0"/>
            <geometry>
                 <box size = "0.02 0.02 0.2"/>
            </geometry>
        </collision>

        <inertial>
         <mass value="0.1"/>
         <origin xyz = "0.01 0.0 0.1" rpy = "0 0 0"/>
         <inertia ixx="0.0002" ixy="0.0" ixz="0.0" iyy="0.0003" iyz="0.0" izz="0.0003"/>
        </inertial>
    </link>   
    
  <joint name="Actuator7" type="continuous">
    <origin xyz="0 -0.10593 -0.00017505" rpy="-1.5708 -5.5511E-17 9.6396E-17" />
    <parent link="SphericalWrist2_Link" />
    <child link="Bracelet_Link" />
    <axis xyz="0 0 1" />
    <limit effort="9" velocity="10.8727" />
       <sensor name="force_torque" type="force_torque">
          <update_rate>100</update_rate>
        </sensor>
  </joint>

   <transmission name="trans_Actuator7">
      <type>transmission_interface/SimpleTransmission</type>
      <joint name="Actuator7">
        <hardwareInterface>hardware_interface/PositionJointInterface</hardwareInterface>
      </joint>
      <actuator name="motor_Actuator7">
        <hardwareInterface>hardware_interface/PositionJointInterface</hardwareInterface>
        <mechanicalReduction>1</mechanicalReduction>
      </actuator>
    </transmission>

     <joint name="joint_6_t_gripper" type="fixed">
  <origin xyz="0 0 -0.0615250000000001" rpy="3.14159265358979 1.09937075168372E-32 0.0" />
        <parent link="Bracelet_Link"/>
        <child link="robotiq_85_base_link"/>
    </joint>

  <joint name="gripper_tool" type="revolute">
  <origin xyz="-0.03 0.0 0.02" rpy="0 0.0 0" />
        <parent link="right_inner_finger"/>
        <child link="tool"/>
        <limit lower="-2.5" upper="2.5" effort="15" velocity="30.8727" />
        <axis xyz="1 0 0" />
         <dynamics damping="0.0" friction="0.0"/>
    </joint>  
    
    <joint name="tool_mass" type="revolute">
        <axis xyz="1 0 0" />
        <limit effort="2.0" lower="0.0" upper="0.0" velocity="0.01" />
        <origin rpy="0 0 0" xyz="0.0 0 0.0"/>
        <parent link="tool"/>
        <child link="point_mass"/>
    </joint>
    
        <link name="point_mass">
        <visual>
            <origin rpy="0 0 0" xyz="0.01 -0.0 0.16"/>
            <geometry>
                <sphere radius = "0.01"/>
            </geometry>
        </visual>
        <collision>
          <origin xyz="0.0 0 0" rpy="0 0 0"/>
            <geometry>
                 <sphere  radius = "0.01"/>
            </geometry>
        </collision>

        <inertial>
         <mass value="0.001"/>
         <origin xyz="0.01 0.0 0.16" rpy="0 0 0"/>
         <inertia ixx="0.00001" ixy="0.0" ixz="0.0" iyy="0.00001" iyz="0.0" izz="0.00001"/>
        </inertial>
    </link> 
    

   <transmission name="trans_Actuator8">
      <type>transmission_interface/SimpleTransmission</type>
      <joint name="gripper_tool">
        <hardwareInterface>hardware_interface/EffortJointInterface</hardwareInterface>
      </joint>
      <actuator name="motor_Actuator8">
        <hardwareInterface>hardware_interface/EffortJointInterface</hardwareInterface>
        <mechanicalReduction>1</mechanicalReduction>
      </actuator>
    </transmission>

 <gazebo>
    <plugin name="gazebo_ros_control" filename="libgazebo_ros_control.so">
    </plugin>
  </gazebo>
  




</robot>
